Not Found: /favicon.ico
Not Found: /favicon.ico
Internal Server Error: /p/sX720Zx6Wx7oO/
Traceback (most recent call last):
  File "/home/ilya/code/webapps/pastebin-on-python/env/lib/python3.12/site-packages/django/core/handlers/exception.py", line 55, in inner
    response = get_response(request)
               ^^^^^^^^^^^^^^^^^^^^^
  File "/home/ilya/code/webapps/pastebin-on-python/env/lib/python3.12/site-packages/django/core/handlers/base.py", line 197, in _get_response
    response = wrapped_callback(request, *callback_args, **callback_kwargs)
               ^^^^^^^^^^^^^^^^^^^^^^^^^^^^^^^^^^^^^^^^^^^^^^^^^^^^^^^^^^^^
  File "/home/ilya/code/webapps/pastebin-on-python/env/lib/python3.12/site-packages/asgiref/sync.py", line 254, in __call__
    return call_result.result()
           ^^^^^^^^^^^^^^^^^^^^
  File "/usr/bin/Python3.12/lib/python3.12/concurrent/futures/_base.py", line 449, in result
    return self.__get_result()
           ^^^^^^^^^^^^^^^^^^^
  File "/usr/bin/Python3.12/lib/python3.12/concurrent/futures/_base.py", line 401, in __get_result
    raise self._exception
  File "/home/ilya/code/webapps/pastebin-on-python/env/lib/python3.12/site-packages/asgiref/sync.py", line 331, in main_wrap
    result = await self.awaitable(*args, **kwargs)
             ^^^^^^^^^^^^^^^^^^^^^^^^^^^^^^^^^^^^^
  File "/home/ilya/code/webapps/pastebin-on-python/pastebin/getpost/views.py", line 35, in get_text_view
    return render(request, 'getpost/post.html', context={'post_text': post_content, 'views': post.views})
                                                                                             ^^^^
NameError: name 'post' is not defined
[2024-09-24 07:44:59.814706] Ошибка загрузки контента из S3! An error occurred (InternalError) when calling the GetObject operation (reached max retries: 4): We encountered an internal error, please try again.
[2024-09-24 07:45:13.354432] Ошибка загрузки контента из S3! An error occurred (InternalError) when calling the GetObject operation (reached max retries: 4): We encountered an internal error, please try again.
[2024-09-24 07:47:24.203894] Ошибка загрузки контента из S3! An error occurred (InternalError) when calling the GetObject operation (reached max retries: 4): We encountered an internal error, please try again.
[2024-09-24 07:47:24.341187] Ошибка загрузки контента из S3! An error occurred (InternalError) when calling the GetObject operation (reached max retries: 4): We encountered an internal error, please try again.
