Not Found: /favicon.ico
Not Found: /favicon.ico
Internal Server Error: /p/sX720Zx6Wx7oO/
Traceback (most recent call last):
  File "/home/ilya/code/webapps/pastebin-on-python/env/lib/python3.12/site-packages/django/core/handlers/exception.py", line 55, in inner
    response = get_response(request)
               ^^^^^^^^^^^^^^^^^^^^^
  File "/home/ilya/code/webapps/pastebin-on-python/env/lib/python3.12/site-packages/django/core/handlers/base.py", line 197, in _get_response
    response = wrapped_callback(request, *callback_args, **callback_kwargs)
               ^^^^^^^^^^^^^^^^^^^^^^^^^^^^^^^^^^^^^^^^^^^^^^^^^^^^^^^^^^^^
  File "/home/ilya/code/webapps/pastebin-on-python/env/lib/python3.12/site-packages/asgiref/sync.py", line 254, in __call__
    return call_result.result()
           ^^^^^^^^^^^^^^^^^^^^
  File "/usr/bin/Python3.12/lib/python3.12/concurrent/futures/_base.py", line 449, in result
    return self.__get_result()
           ^^^^^^^^^^^^^^^^^^^
  File "/usr/bin/Python3.12/lib/python3.12/concurrent/futures/_base.py", line 401, in __get_result
    raise self._exception
  File "/home/ilya/code/webapps/pastebin-on-python/env/lib/python3.12/site-packages/asgiref/sync.py", line 331, in main_wrap
    result = await self.awaitable(*args, **kwargs)
             ^^^^^^^^^^^^^^^^^^^^^^^^^^^^^^^^^^^^^
  File "/home/ilya/code/webapps/pastebin-on-python/pastebin/getpost/views.py", line 35, in get_text_view
    return render(request, 'getpost/post.html', context={'post_text': post_content, 'views': post.views})
                                                                                             ^^^^
NameError: name 'post' is not defined
[2024-09-24 07:44:59.814706] Ошибка загрузки контента из S3! An error occurred (InternalError) when calling the GetObject operation (reached max retries: 4): We encountered an internal error, please try again.
[2024-09-24 07:45:13.354432] Ошибка загрузки контента из S3! An error occurred (InternalError) when calling the GetObject operation (reached max retries: 4): We encountered an internal error, please try again.
[2024-09-24 07:47:24.203894] Ошибка загрузки контента из S3! An error occurred (InternalError) when calling the GetObject operation (reached max retries: 4): We encountered an internal error, please try again.
[2024-09-24 07:47:24.341187] Ошибка загрузки контента из S3! An error occurred (InternalError) when calling the GetObject operation (reached max retries: 4): We encountered an internal error, please try again.
Not Found: /favicon.ico
[2024-09-27 01:13:32.365040] Ошибка при запросе к микросервису для генерации ключа! All connection attempts failed
Internal Server Error: /
Traceback (most recent call last):
  File "/home/ilya/code/webapps/pastebin-on-python/env/lib/python3.12/site-packages/django/core/handlers/exception.py", line 55, in inner
    response = get_response(request)
               ^^^^^^^^^^^^^^^^^^^^^
  File "/home/ilya/code/webapps/pastebin-on-python/env/lib/python3.12/site-packages/django/core/handlers/base.py", line 197, in _get_response
    response = wrapped_callback(request, *callback_args, **callback_kwargs)
               ^^^^^^^^^^^^^^^^^^^^^^^^^^^^^^^^^^^^^^^^^^^^^^^^^^^^^^^^^^^^
  File "/home/ilya/code/webapps/pastebin-on-python/env/lib/python3.12/site-packages/asgiref/sync.py", line 254, in __call__
    return call_result.result()
           ^^^^^^^^^^^^^^^^^^^^
  File "/usr/bin/Python3.12/lib/python3.12/concurrent/futures/_base.py", line 449, in result
    return self.__get_result()
           ^^^^^^^^^^^^^^^^^^^
  File "/usr/bin/Python3.12/lib/python3.12/concurrent/futures/_base.py", line 401, in __get_result
    raise self._exception
  File "/home/ilya/code/webapps/pastebin-on-python/env/lib/python3.12/site-packages/asgiref/sync.py", line 331, in main_wrap
    result = await self.awaitable(*args, **kwargs)
             ^^^^^^^^^^^^^^^^^^^^^^^^^^^^^^^^^^^^^
  File "/home/ilya/code/webapps/pastebin-on-python/pastebin/savepost/views.py", line 40, in post
    post_key = response_json['hash']
        ^^^^^^^^^^^^^
UnboundLocalError: cannot access local variable 'response_json' where it is not associated with a value
[2024-09-27 01:15:02.785604] Ошибка запроса к хранилищу при записи файла в облако: An error occurred (RequestTimeTooSkewed) when calling the PutObject operation: The difference between the request time and the current time is too large.
[2024-09-27 01:15:11.109665] Ошибка загрузки контента из S3! An error occurred (RequestTimeTooSkewed) when calling the GetObject operation: The difference between the request time and the current time is too large.
Internal Server Error: /
Traceback (most recent call last):
  File "/home/ilya/code/webapps/pastebin-on-python/env/lib/python3.12/site-packages/django/core/handlers/exception.py", line 55, in inner
    response = get_response(request)
               ^^^^^^^^^^^^^^^^^^^^^
  File "/home/ilya/code/webapps/pastebin-on-python/env/lib/python3.12/site-packages/django/core/handlers/base.py", line 197, in _get_response
    response = wrapped_callback(request, *callback_args, **callback_kwargs)
               ^^^^^^^^^^^^^^^^^^^^^^^^^^^^^^^^^^^^^^^^^^^^^^^^^^^^^^^^^^^^
  File "/home/ilya/code/webapps/pastebin-on-python/env/lib/python3.12/site-packages/asgiref/sync.py", line 254, in __call__
    return call_result.result()
           ^^^^^^^^^^^^^^^^^^^^
  File "/usr/bin/Python3.12/lib/python3.12/concurrent/futures/_base.py", line 449, in result
    return self.__get_result()
           ^^^^^^^^^^^^^^^^^^^
  File "/usr/bin/Python3.12/lib/python3.12/concurrent/futures/_base.py", line 401, in __get_result
    raise self._exception
  File "/home/ilya/code/webapps/pastebin-on-python/env/lib/python3.12/site-packages/asgiref/sync.py", line 331, in main_wrap
    result = await self.awaitable(*args, **kwargs)
             ^^^^^^^^^^^^^^^^^^^^^^^^^^^^^^^^^^^^^
  File "/home/ilya/code/webapps/pastebin-on-python/pastebin/savepost/views.py", line 46, in post
    await date_validator(del_date)
  File "/home/ilya/code/webapps/pastebin-on-python/pastebin/savepost/validators.py", line 8, in date_validator
    date_with_time =datetime.strptime(input_date)
                    ^^^^^^^^^^^^^^^^^^^^^^^^^^^^^
TypeError: strptime() takes exactly 2 arguments (1 given)
Internal Server Error: /
Traceback (most recent call last):
  File "/home/ilya/code/webapps/pastebin-on-python/env/lib/python3.12/site-packages/django/core/handlers/exception.py", line 55, in inner
    response = get_response(request)
               ^^^^^^^^^^^^^^^^^^^^^
  File "/home/ilya/code/webapps/pastebin-on-python/env/lib/python3.12/site-packages/django/core/handlers/base.py", line 197, in _get_response
    response = wrapped_callback(request, *callback_args, **callback_kwargs)
               ^^^^^^^^^^^^^^^^^^^^^^^^^^^^^^^^^^^^^^^^^^^^^^^^^^^^^^^^^^^^
  File "/home/ilya/code/webapps/pastebin-on-python/env/lib/python3.12/site-packages/asgiref/sync.py", line 254, in __call__
    return call_result.result()
           ^^^^^^^^^^^^^^^^^^^^
  File "/usr/bin/Python3.12/lib/python3.12/concurrent/futures/_base.py", line 449, in result
    return self.__get_result()
           ^^^^^^^^^^^^^^^^^^^
  File "/usr/bin/Python3.12/lib/python3.12/concurrent/futures/_base.py", line 401, in __get_result
    raise self._exception
  File "/home/ilya/code/webapps/pastebin-on-python/env/lib/python3.12/site-packages/asgiref/sync.py", line 331, in main_wrap
    result = await self.awaitable(*args, **kwargs)
             ^^^^^^^^^^^^^^^^^^^^^^^^^^^^^^^^^^^^^
  File "/home/ilya/code/webapps/pastebin-on-python/pastebin/savepost/views.py", line 47, in post
    await date_validator(del_date)
  File "/home/ilya/code/webapps/pastebin-on-python/pastebin/savepost/validators.py", line 7, in date_validator
    date_with_time =datetime.strptime(input_date)
                    ^^^^^^^^^^^^^^^^^^^^^^^^^^^^^
TypeError: strptime() takes exactly 2 arguments (1 given)
Internal Server Error: /
Traceback (most recent call last):
  File "/home/ilya/code/webapps/pastebin-on-python/env/lib/python3.12/site-packages/django/core/handlers/exception.py", line 55, in inner
    response = get_response(request)
               ^^^^^^^^^^^^^^^^^^^^^
  File "/home/ilya/code/webapps/pastebin-on-python/env/lib/python3.12/site-packages/django/core/handlers/base.py", line 197, in _get_response
    response = wrapped_callback(request, *callback_args, **callback_kwargs)
               ^^^^^^^^^^^^^^^^^^^^^^^^^^^^^^^^^^^^^^^^^^^^^^^^^^^^^^^^^^^^
  File "/home/ilya/code/webapps/pastebin-on-python/env/lib/python3.12/site-packages/asgiref/sync.py", line 254, in __call__
    return call_result.result()
           ^^^^^^^^^^^^^^^^^^^^
  File "/usr/bin/Python3.12/lib/python3.12/concurrent/futures/_base.py", line 449, in result
    return self.__get_result()
           ^^^^^^^^^^^^^^^^^^^
  File "/usr/bin/Python3.12/lib/python3.12/concurrent/futures/_base.py", line 401, in __get_result
    raise self._exception
  File "/home/ilya/code/webapps/pastebin-on-python/env/lib/python3.12/site-packages/asgiref/sync.py", line 331, in main_wrap
    result = await self.awaitable(*args, **kwargs)
             ^^^^^^^^^^^^^^^^^^^^^^^^^^^^^^^^^^^^^
  File "/home/ilya/code/webapps/pastebin-on-python/pastebin/savepost/views.py", line 47, in post
    await date_validator(del_date)
  File "/home/ilya/code/webapps/pastebin-on-python/pastebin/savepost/validators.py", line 9, in date_validator
    max_date = today + datetime.timedelta(days=14)
                       ^^^^^^^^^^^^^^^^^^
AttributeError: type object 'datetime.datetime' has no attribute 'timedelta'
Not Found: /favicon.ico
Not Found: /favicon.ico
Not Found: /favicon.ico
Not Found: /favicon.ico
Not Found: /favicon.ico
Not Found: /favicon.ico
Not Found: /favicon.ico
Not Found: /favicon.ico
Not Found: /favicon.ico
Not Found: /favicon.ico
Not Found: /favicon.ico
Not Found: /(/static/JS/online_interpreter.js)
Not Found: /execute_code/
Not Found: /favicon.ico
Not Found: /favicon.ico
Not Found: /favicon.ico
Not Found: /favicon.ico
Not Found: /favicon.ico
[2024-09-30 13:32:56.524241] Ошибка при запросе к микросервису для генерации ключа! All connection attempts failed
Internal Server Error: /
Traceback (most recent call last):
  File "/home/ilya/code/webapps/pastebin-on-python/env/lib/python3.12/site-packages/django/core/handlers/exception.py", line 55, in inner
    response = get_response(request)
               ^^^^^^^^^^^^^^^^^^^^^
  File "/home/ilya/code/webapps/pastebin-on-python/env/lib/python3.12/site-packages/django/core/handlers/base.py", line 197, in _get_response
    response = wrapped_callback(request, *callback_args, **callback_kwargs)
               ^^^^^^^^^^^^^^^^^^^^^^^^^^^^^^^^^^^^^^^^^^^^^^^^^^^^^^^^^^^^
  File "/home/ilya/code/webapps/pastebin-on-python/env/lib/python3.12/site-packages/asgiref/sync.py", line 254, in __call__
    return call_result.result()
           ^^^^^^^^^^^^^^^^^^^^
  File "/usr/bin/Python3.12/lib/python3.12/concurrent/futures/_base.py", line 449, in result
    return self.__get_result()
           ^^^^^^^^^^^^^^^^^^^
  File "/usr/bin/Python3.12/lib/python3.12/concurrent/futures/_base.py", line 401, in __get_result
    raise self._exception
  File "/home/ilya/code/webapps/pastebin-on-python/env/lib/python3.12/site-packages/asgiref/sync.py", line 331, in main_wrap
    result = await self.awaitable(*args, **kwargs)
             ^^^^^^^^^^^^^^^^^^^^^^^^^^^^^^^^^^^^^
  File "/home/ilya/code/webapps/pastebin-on-python/pastebin/savepost/views.py", line 32, in post
    await upload_file_to_s3(post_content, post_key)
  File "/home/ilya/code/webapps/pastebin-on-python/pastebin/savepost/yandex_s3.py", line 14, in upload_file_to_s3
    key += '.txt'
TypeError: unsupported operand type(s) for +=: 'NoneType' and 'str'
Not Found: /favicon.ico
Internal Server Error: /
Traceback (most recent call last):
  File "/home/ilya/code/webapps/pastebin-on-python/env/lib/python3.12/site-packages/django/urls/base.py", line 71, in reverse
    extra, resolver = resolver.namespace_dict[ns]
                      ~~~~~~~~~~~~~~~~~~~~~~~^^^^
KeyError: 'savepost'

During handling of the above exception, another exception occurred:

Traceback (most recent call last):
  File "/home/ilya/code/webapps/pastebin-on-python/env/lib/python3.12/site-packages/django/core/handlers/exception.py", line 55, in inner
    response = get_response(request)
               ^^^^^^^^^^^^^^^^^^^^^
  File "/home/ilya/code/webapps/pastebin-on-python/env/lib/python3.12/site-packages/django/core/handlers/base.py", line 197, in _get_response
    response = wrapped_callback(request, *callback_args, **callback_kwargs)
               ^^^^^^^^^^^^^^^^^^^^^^^^^^^^^^^^^^^^^^^^^^^^^^^^^^^^^^^^^^^^
  File "/home/ilya/code/webapps/pastebin-on-python/env/lib/python3.12/site-packages/asgiref/sync.py", line 254, in __call__
    return call_result.result()
           ^^^^^^^^^^^^^^^^^^^^
  File "/usr/bin/Python3.12/lib/python3.12/concurrent/futures/_base.py", line 449, in result
    return self.__get_result()
           ^^^^^^^^^^^^^^^^^^^
  File "/usr/bin/Python3.12/lib/python3.12/concurrent/futures/_base.py", line 401, in __get_result
    raise self._exception
  File "/home/ilya/code/webapps/pastebin-on-python/env/lib/python3.12/site-packages/asgiref/sync.py", line 331, in main_wrap
    result = await self.awaitable(*args, **kwargs)
             ^^^^^^^^^^^^^^^^^^^^^^^^^^^^^^^^^^^^^
  File "/home/ilya/code/webapps/pastebin-on-python/pastebin/post/views.py", line 20, in get
    return render(self.request, self.template_name)
           ^^^^^^^^^^^^^^^^^^^^^^^^^^^^^^^^^^^^^^^^
  File "/home/ilya/code/webapps/pastebin-on-python/env/lib/python3.12/site-packages/django/shortcuts.py", line 24, in render
    content = loader.render_to_string(template_name, context, request, using=using)
              ^^^^^^^^^^^^^^^^^^^^^^^^^^^^^^^^^^^^^^^^^^^^^^^^^^^^^^^^^^^^^^^^^^^^^
  File "/home/ilya/code/webapps/pastebin-on-python/env/lib/python3.12/site-packages/django/template/loader.py", line 62, in render_to_string
    return template.render(context, request)
           ^^^^^^^^^^^^^^^^^^^^^^^^^^^^^^^^^
  File "/home/ilya/code/webapps/pastebin-on-python/env/lib/python3.12/site-packages/django/template/backends/django.py", line 61, in render
    return self.template.render(context)
           ^^^^^^^^^^^^^^^^^^^^^^^^^^^^^
  File "/home/ilya/code/webapps/pastebin-on-python/env/lib/python3.12/site-packages/django/template/base.py", line 175, in render
    return self._render(context)
           ^^^^^^^^^^^^^^^^^^^^^
  File "/home/ilya/code/webapps/pastebin-on-python/env/lib/python3.12/site-packages/django/template/base.py", line 167, in _render
    return self.nodelist.render(context)
           ^^^^^^^^^^^^^^^^^^^^^^^^^^^^^
  File "/home/ilya/code/webapps/pastebin-on-python/env/lib/python3.12/site-packages/django/template/base.py", line 1005, in render
    return SafeString("".join([node.render_annotated(context) for node in self]))
                               ^^^^^^^^^^^^^^^^^^^^^^^^^^^^^^
  File "/home/ilya/code/webapps/pastebin-on-python/env/lib/python3.12/site-packages/django/template/base.py", line 966, in render_annotated
    return self.render(context)
           ^^^^^^^^^^^^^^^^^^^^
  File "/home/ilya/code/webapps/pastebin-on-python/env/lib/python3.12/site-packages/django/template/defaulttags.py", line 471, in render
    url = reverse(view_name, args=args, kwargs=kwargs, current_app=current_app)
          ^^^^^^^^^^^^^^^^^^^^^^^^^^^^^^^^^^^^^^^^^^^^^^^^^^^^^^^^^^^^^^^^^^^^^
  File "/home/ilya/code/webapps/pastebin-on-python/env/lib/python3.12/site-packages/django/urls/base.py", line 82, in reverse
    raise NoReverseMatch("%s is not a registered namespace" % key)
django.urls.exceptions.NoReverseMatch: 'savepost' is not a registered namespace
[2024-10-10 19:57:40.433006] Ошибка при запросе к микросервису для генерации ключа! All connection attempts failed
Internal Server Error: /
Traceback (most recent call last):
  File "/home/ilya/code/webapps/pastebin-on-python/env/lib/python3.12/site-packages/django/core/handlers/exception.py", line 55, in inner
    response = get_response(request)
               ^^^^^^^^^^^^^^^^^^^^^
  File "/home/ilya/code/webapps/pastebin-on-python/env/lib/python3.12/site-packages/django/core/handlers/base.py", line 197, in _get_response
    response = wrapped_callback(request, *callback_args, **callback_kwargs)
               ^^^^^^^^^^^^^^^^^^^^^^^^^^^^^^^^^^^^^^^^^^^^^^^^^^^^^^^^^^^^
  File "/home/ilya/code/webapps/pastebin-on-python/env/lib/python3.12/site-packages/asgiref/sync.py", line 254, in __call__
    return call_result.result()
           ^^^^^^^^^^^^^^^^^^^^
  File "/usr/bin/Python3.12/lib/python3.12/concurrent/futures/_base.py", line 449, in result
    return self.__get_result()
           ^^^^^^^^^^^^^^^^^^^
  File "/usr/bin/Python3.12/lib/python3.12/concurrent/futures/_base.py", line 401, in __get_result
    raise self._exception
  File "/home/ilya/code/webapps/pastebin-on-python/env/lib/python3.12/site-packages/asgiref/sync.py", line 331, in main_wrap
    result = await self.awaitable(*args, **kwargs)
             ^^^^^^^^^^^^^^^^^^^^^^^^^^^^^^^^^^^^^
  File "/home/ilya/code/webapps/pastebin-on-python/pastebin/post/views.py", line 34, in post
    post_key += '.txt'
TypeError: unsupported operand type(s) for +=: 'NoneType' and 'str'
[2024-10-10 19:58:56.698558] Ошибка запроса к хранилищу при записи файла в облако: An error occurred (RequestTimeTooSkewed) when calling the PutObject operation: The difference between the request time and the current time is too large.
Internal Server Error: /
Traceback (most recent call last):
  File "/home/ilya/code/webapps/pastebin-on-python/env/lib/python3.12/site-packages/django/core/handlers/exception.py", line 55, in inner
    response = get_response(request)
               ^^^^^^^^^^^^^^^^^^^^^
  File "/home/ilya/code/webapps/pastebin-on-python/env/lib/python3.12/site-packages/django/core/handlers/base.py", line 197, in _get_response
    response = wrapped_callback(request, *callback_args, **callback_kwargs)
               ^^^^^^^^^^^^^^^^^^^^^^^^^^^^^^^^^^^^^^^^^^^^^^^^^^^^^^^^^^^^
  File "/home/ilya/code/webapps/pastebin-on-python/env/lib/python3.12/site-packages/asgiref/sync.py", line 254, in __call__
    return call_result.result()
           ^^^^^^^^^^^^^^^^^^^^
  File "/usr/bin/Python3.12/lib/python3.12/concurrent/futures/_base.py", line 449, in result
    return self.__get_result()
           ^^^^^^^^^^^^^^^^^^^
  File "/usr/bin/Python3.12/lib/python3.12/concurrent/futures/_base.py", line 401, in __get_result
    raise self._exception
  File "/home/ilya/code/webapps/pastebin-on-python/env/lib/python3.12/site-packages/asgiref/sync.py", line 331, in main_wrap
    result = await self.awaitable(*args, **kwargs)
             ^^^^^^^^^^^^^^^^^^^^^^^^^^^^^^^^^^^^^
  File "/home/ilya/code/webapps/pastebin-on-python/pastebin/post/views.py", line 36, in post
    await Posts.objects.acreate(key=post_key, del_date=del_date)
  File "/home/ilya/code/webapps/pastebin-on-python/env/lib/python3.12/site-packages/django/db/models/query.py", line 662, in acreate
    return await sync_to_async(self.create)(**kwargs)
           ^^^^^^^^^^^^^^^^^^^^^^^^^^^^^^^^^^^^^^^^^^
  File "/home/ilya/code/webapps/pastebin-on-python/env/lib/python3.12/site-packages/asgiref/sync.py", line 468, in __call__
    ret = await asyncio.shield(exec_coro)
          ^^^^^^^^^^^^^^^^^^^^^^^^^^^^^^^
  File "/home/ilya/code/webapps/pastebin-on-python/env/lib/python3.12/site-packages/asgiref/current_thread_executor.py", line 40, in run
    result = self.fn(*self.args, **self.kwargs)
             ^^^^^^^^^^^^^^^^^^^^^^^^^^^^^^^^^^
  File "/home/ilya/code/webapps/pastebin-on-python/env/lib/python3.12/site-packages/asgiref/sync.py", line 522, in thread_handler
    return func(*args, **kwargs)
           ^^^^^^^^^^^^^^^^^^^^^
  File "/home/ilya/code/webapps/pastebin-on-python/env/lib/python3.12/site-packages/django/db/models/query.py", line 656, in create
    obj = self.model(**kwargs)
          ^^^^^^^^^^^^^^^^^^^^
  File "/home/ilya/code/webapps/pastebin-on-python/env/lib/python3.12/site-packages/django/db/models/base.py", line 567, in __init__
    raise TypeError(
TypeError: Posts() got unexpected keyword arguments: 'del_date'
[2024-10-10 19:59:23.349576] Ошибка запроса к хранилищу при записи файла в облако: An error occurred (RequestTimeTooSkewed) when calling the PutObject operation: The difference between the request time and the current time is too large.
[2024-10-10 19:59:38.687313] Ошибка загрузки контента из S3! An error occurred (RequestTimeTooSkewed) when calling the GetObject operation: The difference between the request time and the current time is too large.
Internal Server Error: /p/XTifXi40xrC62.txt/
Traceback (most recent call last):
  File "/home/ilya/code/webapps/pastebin-on-python/env/lib/python3.12/site-packages/django/core/handlers/exception.py", line 55, in inner
    response = get_response(request)
               ^^^^^^^^^^^^^^^^^^^^^
  File "/home/ilya/code/webapps/pastebin-on-python/env/lib/python3.12/site-packages/django/core/handlers/base.py", line 197, in _get_response
    response = wrapped_callback(request, *callback_args, **callback_kwargs)
               ^^^^^^^^^^^^^^^^^^^^^^^^^^^^^^^^^^^^^^^^^^^^^^^^^^^^^^^^^^^^
  File "/home/ilya/code/webapps/pastebin-on-python/env/lib/python3.12/site-packages/asgiref/sync.py", line 254, in __call__
    return call_result.result()
           ^^^^^^^^^^^^^^^^^^^^
  File "/usr/bin/Python3.12/lib/python3.12/concurrent/futures/_base.py", line 449, in result
    return self.__get_result()
           ^^^^^^^^^^^^^^^^^^^
  File "/usr/bin/Python3.12/lib/python3.12/concurrent/futures/_base.py", line 401, in __get_result
    raise self._exception
  File "/home/ilya/code/webapps/pastebin-on-python/env/lib/python3.12/site-packages/asgiref/sync.py", line 331, in main_wrap
    result = await self.awaitable(*args, **kwargs)
             ^^^^^^^^^^^^^^^^^^^^^^^^^^^^^^^^^^^^^
  File "/home/ilya/code/webapps/pastebin-on-python/pastebin/post/views.py", line 73, in get_post_view
    return render(request, 'post/post.html', context={'post_text': post_content, 'views': post_db_row.views})
                                                                                          ^^^^^^^^^^^^^^^^^
AttributeError: 'Posts' object has no attribute 'views'
[2024-10-10 20:00:30.296765] Ошибка загрузки контента из S3! An error occurred (RequestTimeTooSkewed) when calling the GetObject operation: The difference between the request time and the current time is too large.
Internal Server Error: /p/XTifXi40xrC62.txt/
Traceback (most recent call last):
  File "/home/ilya/code/webapps/pastebin-on-python/env/lib/python3.12/site-packages/django/core/handlers/exception.py", line 55, in inner
    response = get_response(request)
               ^^^^^^^^^^^^^^^^^^^^^
  File "/home/ilya/code/webapps/pastebin-on-python/env/lib/python3.12/site-packages/django/core/handlers/base.py", line 197, in _get_response
    response = wrapped_callback(request, *callback_args, **callback_kwargs)
               ^^^^^^^^^^^^^^^^^^^^^^^^^^^^^^^^^^^^^^^^^^^^^^^^^^^^^^^^^^^^
  File "/home/ilya/code/webapps/pastebin-on-python/env/lib/python3.12/site-packages/asgiref/sync.py", line 254, in __call__
    return call_result.result()
           ^^^^^^^^^^^^^^^^^^^^
  File "/usr/bin/Python3.12/lib/python3.12/concurrent/futures/_base.py", line 449, in result
    return self.__get_result()
           ^^^^^^^^^^^^^^^^^^^
  File "/usr/bin/Python3.12/lib/python3.12/concurrent/futures/_base.py", line 401, in __get_result
    raise self._exception
  File "/home/ilya/code/webapps/pastebin-on-python/env/lib/python3.12/site-packages/asgiref/sync.py", line 331, in main_wrap
    result = await self.awaitable(*args, **kwargs)
             ^^^^^^^^^^^^^^^^^^^^^^^^^^^^^^^^^^^^^
  File "/home/ilya/code/webapps/pastebin-on-python/pastebin/post/views.py", line 73, in get_post_view
    return render(request, 'post/post.html', context={'post_text': post_content, 'views': post_db_row.views_count})
           ^^^^^^^^^^^^^^^^^^^^^^^^^^^^^^^^^^^^^^^^^^^^^^^^^^^^^^^^^^^^^^^^^^^^^^^^^^^^^^^^^^^^^^^^^^^^^^^^^^^^^^^^
  File "/home/ilya/code/webapps/pastebin-on-python/env/lib/python3.12/site-packages/django/shortcuts.py", line 24, in render
    content = loader.render_to_string(template_name, context, request, using=using)
              ^^^^^^^^^^^^^^^^^^^^^^^^^^^^^^^^^^^^^^^^^^^^^^^^^^^^^^^^^^^^^^^^^^^^^
  File "/home/ilya/code/webapps/pastebin-on-python/env/lib/python3.12/site-packages/django/template/loader.py", line 61, in render_to_string
    template = get_template(template_name, using=using)
               ^^^^^^^^^^^^^^^^^^^^^^^^^^^^^^^^^^^^^^^^
  File "/home/ilya/code/webapps/pastebin-on-python/env/lib/python3.12/site-packages/django/template/loader.py", line 19, in get_template
    raise TemplateDoesNotExist(template_name, chain=chain)
django.template.exceptions.TemplateDoesNotExist: post/post.html
Internal Server Error: /p/XTifXi40xrC62/
Traceback (most recent call last):
  File "/home/ilya/code/webapps/pastebin-on-python/pastebin/post/views.py", line 60, in get_post_view
    post_db_row = await Posts.objects.aget(key=post_key)
                  ^^^^^^^^^^^^^^^^^^^^^^^^^^^^^^^^^^^^^^
  File "/home/ilya/code/webapps/pastebin-on-python/env/lib/python3.12/site-packages/django/db/models/query.py", line 649, in aget
    return await sync_to_async(self.get)(*args, **kwargs)
           ^^^^^^^^^^^^^^^^^^^^^^^^^^^^^^^^^^^^^^^^^^^^^^
  File "/home/ilya/code/webapps/pastebin-on-python/env/lib/python3.12/site-packages/asgiref/sync.py", line 468, in __call__
    ret = await asyncio.shield(exec_coro)
          ^^^^^^^^^^^^^^^^^^^^^^^^^^^^^^^
  File "/home/ilya/code/webapps/pastebin-on-python/env/lib/python3.12/site-packages/asgiref/current_thread_executor.py", line 40, in run
    result = self.fn(*self.args, **self.kwargs)
             ^^^^^^^^^^^^^^^^^^^^^^^^^^^^^^^^^^
  File "/home/ilya/code/webapps/pastebin-on-python/env/lib/python3.12/site-packages/asgiref/sync.py", line 522, in thread_handler
    return func(*args, **kwargs)
           ^^^^^^^^^^^^^^^^^^^^^
  File "/home/ilya/code/webapps/pastebin-on-python/env/lib/python3.12/site-packages/django/db/models/query.py", line 637, in get
    raise self.model.DoesNotExist(
post.models.Posts.DoesNotExist: Posts matching query does not exist.

During handling of the above exception, another exception occurred:

Traceback (most recent call last):
  File "/home/ilya/code/webapps/pastebin-on-python/env/lib/python3.12/site-packages/django/core/handlers/exception.py", line 55, in inner
    response = get_response(request)
               ^^^^^^^^^^^^^^^^^^^^^
  File "/home/ilya/code/webapps/pastebin-on-python/env/lib/python3.12/site-packages/django/core/handlers/base.py", line 197, in _get_response
    response = wrapped_callback(request, *callback_args, **callback_kwargs)
               ^^^^^^^^^^^^^^^^^^^^^^^^^^^^^^^^^^^^^^^^^^^^^^^^^^^^^^^^^^^^
  File "/home/ilya/code/webapps/pastebin-on-python/env/lib/python3.12/site-packages/asgiref/sync.py", line 254, in __call__
    return call_result.result()
           ^^^^^^^^^^^^^^^^^^^^
  File "/usr/bin/Python3.12/lib/python3.12/concurrent/futures/_base.py", line 449, in result
    return self.__get_result()
           ^^^^^^^^^^^^^^^^^^^
  File "/usr/bin/Python3.12/lib/python3.12/concurrent/futures/_base.py", line 401, in __get_result
    raise self._exception
  File "/home/ilya/code/webapps/pastebin-on-python/env/lib/python3.12/site-packages/asgiref/sync.py", line 331, in main_wrap
    result = await self.awaitable(*args, **kwargs)
             ^^^^^^^^^^^^^^^^^^^^^^^^^^^^^^^^^^^^^
  File "/home/ilya/code/webapps/pastebin-on-python/pastebin/post/views.py", line 62, in get_post_view
    return render(request, 'post/post.html',
           ^^^^^^^^^^^^^^^^^^^^^^^^^^^^^^^^^
  File "/home/ilya/code/webapps/pastebin-on-python/env/lib/python3.12/site-packages/django/shortcuts.py", line 24, in render
    content = loader.render_to_string(template_name, context, request, using=using)
              ^^^^^^^^^^^^^^^^^^^^^^^^^^^^^^^^^^^^^^^^^^^^^^^^^^^^^^^^^^^^^^^^^^^^^
  File "/home/ilya/code/webapps/pastebin-on-python/env/lib/python3.12/site-packages/django/template/loader.py", line 61, in render_to_string
    template = get_template(template_name, using=using)
               ^^^^^^^^^^^^^^^^^^^^^^^^^^^^^^^^^^^^^^^^
  File "/home/ilya/code/webapps/pastebin-on-python/env/lib/python3.12/site-packages/django/template/loader.py", line 19, in get_template
    raise TemplateDoesNotExist(template_name, chain=chain)
django.template.exceptions.TemplateDoesNotExist: post/post.html
[2024-10-10 20:02:43.340110] Ошибка запроса к хранилищу при записи файла в облако: An error occurred (RequestTimeTooSkewed) when calling the PutObject operation: The difference between the request time and the current time is too large.
[2024-10-10 20:02:47.825025] Ошибка загрузки контента из S3! An error occurred (RequestTimeTooSkewed) when calling the GetObject operation: The difference between the request time and the current time is too large.
Internal Server Error: /p/E2cQd7ZqKYdKJ/
Traceback (most recent call last):
  File "/home/ilya/code/webapps/pastebin-on-python/env/lib/python3.12/site-packages/django/core/handlers/exception.py", line 55, in inner
    response = get_response(request)
               ^^^^^^^^^^^^^^^^^^^^^
  File "/home/ilya/code/webapps/pastebin-on-python/env/lib/python3.12/site-packages/django/core/handlers/base.py", line 197, in _get_response
    response = wrapped_callback(request, *callback_args, **callback_kwargs)
               ^^^^^^^^^^^^^^^^^^^^^^^^^^^^^^^^^^^^^^^^^^^^^^^^^^^^^^^^^^^^
  File "/home/ilya/code/webapps/pastebin-on-python/env/lib/python3.12/site-packages/asgiref/sync.py", line 254, in __call__
    return call_result.result()
           ^^^^^^^^^^^^^^^^^^^^
  File "/usr/bin/Python3.12/lib/python3.12/concurrent/futures/_base.py", line 449, in result
    return self.__get_result()
           ^^^^^^^^^^^^^^^^^^^
  File "/usr/bin/Python3.12/lib/python3.12/concurrent/futures/_base.py", line 401, in __get_result
    raise self._exception
  File "/home/ilya/code/webapps/pastebin-on-python/env/lib/python3.12/site-packages/asgiref/sync.py", line 331, in main_wrap
    result = await self.awaitable(*args, **kwargs)
             ^^^^^^^^^^^^^^^^^^^^^^^^^^^^^^^^^^^^^
  File "/home/ilya/code/webapps/pastebin-on-python/pastebin/post/views.py", line 73, in get_post_view
    return render(request, 'post/post.html', context={'post_text': post_content, 'views': post_db_row.views_count})
           ^^^^^^^^^^^^^^^^^^^^^^^^^^^^^^^^^^^^^^^^^^^^^^^^^^^^^^^^^^^^^^^^^^^^^^^^^^^^^^^^^^^^^^^^^^^^^^^^^^^^^^^^
  File "/home/ilya/code/webapps/pastebin-on-python/env/lib/python3.12/site-packages/django/shortcuts.py", line 24, in render
    content = loader.render_to_string(template_name, context, request, using=using)
              ^^^^^^^^^^^^^^^^^^^^^^^^^^^^^^^^^^^^^^^^^^^^^^^^^^^^^^^^^^^^^^^^^^^^^
  File "/home/ilya/code/webapps/pastebin-on-python/env/lib/python3.12/site-packages/django/template/loader.py", line 61, in render_to_string
    template = get_template(template_name, using=using)
               ^^^^^^^^^^^^^^^^^^^^^^^^^^^^^^^^^^^^^^^^
  File "/home/ilya/code/webapps/pastebin-on-python/env/lib/python3.12/site-packages/django/template/loader.py", line 19, in get_template
    raise TemplateDoesNotExist(template_name, chain=chain)
django.template.exceptions.TemplateDoesNotExist: post/post.html
[2024-10-10 20:03:33.688472] Ошибка загрузки контента из S3! An error occurred (RequestTimeTooSkewed) when calling the GetObject operation: The difference between the request time and the current time is too large.
Internal Server Error: /p/E2cQd7ZqKYdKJ/
Traceback (most recent call last):
  File "/home/ilya/code/webapps/pastebin-on-python/env/lib/python3.12/site-packages/django/urls/base.py", line 71, in reverse
    extra, resolver = resolver.namespace_dict[ns]
                      ~~~~~~~~~~~~~~~~~~~~~~~^^^^
KeyError: 'savepost'

During handling of the above exception, another exception occurred:

Traceback (most recent call last):
  File "/home/ilya/code/webapps/pastebin-on-python/env/lib/python3.12/site-packages/django/core/handlers/exception.py", line 55, in inner
    response = get_response(request)
               ^^^^^^^^^^^^^^^^^^^^^
  File "/home/ilya/code/webapps/pastebin-on-python/env/lib/python3.12/site-packages/django/core/handlers/base.py", line 197, in _get_response
    response = wrapped_callback(request, *callback_args, **callback_kwargs)
               ^^^^^^^^^^^^^^^^^^^^^^^^^^^^^^^^^^^^^^^^^^^^^^^^^^^^^^^^^^^^
  File "/home/ilya/code/webapps/pastebin-on-python/env/lib/python3.12/site-packages/asgiref/sync.py", line 254, in __call__
    return call_result.result()
           ^^^^^^^^^^^^^^^^^^^^
  File "/usr/bin/Python3.12/lib/python3.12/concurrent/futures/_base.py", line 449, in result
    return self.__get_result()
           ^^^^^^^^^^^^^^^^^^^
  File "/usr/bin/Python3.12/lib/python3.12/concurrent/futures/_base.py", line 401, in __get_result
    raise self._exception
  File "/home/ilya/code/webapps/pastebin-on-python/env/lib/python3.12/site-packages/asgiref/sync.py", line 331, in main_wrap
    result = await self.awaitable(*args, **kwargs)
             ^^^^^^^^^^^^^^^^^^^^^^^^^^^^^^^^^^^^^
  File "/home/ilya/code/webapps/pastebin-on-python/pastebin/post/views.py", line 73, in get_post_view
    return render(request, 'post/post.html', context={'post_text': post_content, 'views': post_db_row.views_count})
           ^^^^^^^^^^^^^^^^^^^^^^^^^^^^^^^^^^^^^^^^^^^^^^^^^^^^^^^^^^^^^^^^^^^^^^^^^^^^^^^^^^^^^^^^^^^^^^^^^^^^^^^^
  File "/home/ilya/code/webapps/pastebin-on-python/env/lib/python3.12/site-packages/django/shortcuts.py", line 24, in render
    content = loader.render_to_string(template_name, context, request, using=using)
              ^^^^^^^^^^^^^^^^^^^^^^^^^^^^^^^^^^^^^^^^^^^^^^^^^^^^^^^^^^^^^^^^^^^^^
  File "/home/ilya/code/webapps/pastebin-on-python/env/lib/python3.12/site-packages/django/template/loader.py", line 62, in render_to_string
    return template.render(context, request)
           ^^^^^^^^^^^^^^^^^^^^^^^^^^^^^^^^^
  File "/home/ilya/code/webapps/pastebin-on-python/env/lib/python3.12/site-packages/django/template/backends/django.py", line 61, in render
    return self.template.render(context)
           ^^^^^^^^^^^^^^^^^^^^^^^^^^^^^
  File "/home/ilya/code/webapps/pastebin-on-python/env/lib/python3.12/site-packages/django/template/base.py", line 175, in render
    return self._render(context)
           ^^^^^^^^^^^^^^^^^^^^^
  File "/home/ilya/code/webapps/pastebin-on-python/env/lib/python3.12/site-packages/django/template/base.py", line 167, in _render
    return self.nodelist.render(context)
           ^^^^^^^^^^^^^^^^^^^^^^^^^^^^^
  File "/home/ilya/code/webapps/pastebin-on-python/env/lib/python3.12/site-packages/django/template/base.py", line 1005, in render
    return SafeString("".join([node.render_annotated(context) for node in self]))
                               ^^^^^^^^^^^^^^^^^^^^^^^^^^^^^^
  File "/home/ilya/code/webapps/pastebin-on-python/env/lib/python3.12/site-packages/django/template/base.py", line 966, in render_annotated
    return self.render(context)
           ^^^^^^^^^^^^^^^^^^^^
  File "/home/ilya/code/webapps/pastebin-on-python/env/lib/python3.12/site-packages/django/template/defaulttags.py", line 471, in render
    url = reverse(view_name, args=args, kwargs=kwargs, current_app=current_app)
          ^^^^^^^^^^^^^^^^^^^^^^^^^^^^^^^^^^^^^^^^^^^^^^^^^^^^^^^^^^^^^^^^^^^^^
  File "/home/ilya/code/webapps/pastebin-on-python/env/lib/python3.12/site-packages/django/urls/base.py", line 82, in reverse
    raise NoReverseMatch("%s is not a registered namespace" % key)
django.urls.exceptions.NoReverseMatch: 'savepost' is not a registered namespace
[2024-10-10 20:03:34.656828] Ошибка загрузки контента из S3! An error occurred (RequestTimeTooSkewed) when calling the GetObject operation: The difference between the request time and the current time is too large.
Internal Server Error: /p/E2cQd7ZqKYdKJ/
Traceback (most recent call last):
  File "/home/ilya/code/webapps/pastebin-on-python/env/lib/python3.12/site-packages/django/urls/base.py", line 71, in reverse
    extra, resolver = resolver.namespace_dict[ns]
                      ~~~~~~~~~~~~~~~~~~~~~~~^^^^
KeyError: 'savepost'

During handling of the above exception, another exception occurred:

Traceback (most recent call last):
  File "/home/ilya/code/webapps/pastebin-on-python/env/lib/python3.12/site-packages/django/core/handlers/exception.py", line 55, in inner
    response = get_response(request)
               ^^^^^^^^^^^^^^^^^^^^^
  File "/home/ilya/code/webapps/pastebin-on-python/env/lib/python3.12/site-packages/django/core/handlers/base.py", line 197, in _get_response
    response = wrapped_callback(request, *callback_args, **callback_kwargs)
               ^^^^^^^^^^^^^^^^^^^^^^^^^^^^^^^^^^^^^^^^^^^^^^^^^^^^^^^^^^^^
  File "/home/ilya/code/webapps/pastebin-on-python/env/lib/python3.12/site-packages/asgiref/sync.py", line 254, in __call__
    return call_result.result()
           ^^^^^^^^^^^^^^^^^^^^
  File "/usr/bin/Python3.12/lib/python3.12/concurrent/futures/_base.py", line 449, in result
    return self.__get_result()
           ^^^^^^^^^^^^^^^^^^^
  File "/usr/bin/Python3.12/lib/python3.12/concurrent/futures/_base.py", line 401, in __get_result
    raise self._exception
  File "/home/ilya/code/webapps/pastebin-on-python/env/lib/python3.12/site-packages/asgiref/sync.py", line 331, in main_wrap
    result = await self.awaitable(*args, **kwargs)
             ^^^^^^^^^^^^^^^^^^^^^^^^^^^^^^^^^^^^^
  File "/home/ilya/code/webapps/pastebin-on-python/pastebin/post/views.py", line 73, in get_post_view
    return render(request, 'post/post.html', context={'post_text': post_content, 'views': post_db_row.views_count})
           ^^^^^^^^^^^^^^^^^^^^^^^^^^^^^^^^^^^^^^^^^^^^^^^^^^^^^^^^^^^^^^^^^^^^^^^^^^^^^^^^^^^^^^^^^^^^^^^^^^^^^^^^
  File "/home/ilya/code/webapps/pastebin-on-python/env/lib/python3.12/site-packages/django/shortcuts.py", line 24, in render
    content = loader.render_to_string(template_name, context, request, using=using)
              ^^^^^^^^^^^^^^^^^^^^^^^^^^^^^^^^^^^^^^^^^^^^^^^^^^^^^^^^^^^^^^^^^^^^^
  File "/home/ilya/code/webapps/pastebin-on-python/env/lib/python3.12/site-packages/django/template/loader.py", line 62, in render_to_string
    return template.render(context, request)
           ^^^^^^^^^^^^^^^^^^^^^^^^^^^^^^^^^
  File "/home/ilya/code/webapps/pastebin-on-python/env/lib/python3.12/site-packages/django/template/backends/django.py", line 61, in render
    return self.template.render(context)
           ^^^^^^^^^^^^^^^^^^^^^^^^^^^^^
  File "/home/ilya/code/webapps/pastebin-on-python/env/lib/python3.12/site-packages/django/template/base.py", line 175, in render
    return self._render(context)
           ^^^^^^^^^^^^^^^^^^^^^
  File "/home/ilya/code/webapps/pastebin-on-python/env/lib/python3.12/site-packages/django/template/base.py", line 167, in _render
    return self.nodelist.render(context)
           ^^^^^^^^^^^^^^^^^^^^^^^^^^^^^
  File "/home/ilya/code/webapps/pastebin-on-python/env/lib/python3.12/site-packages/django/template/base.py", line 1005, in render
    return SafeString("".join([node.render_annotated(context) for node in self]))
                               ^^^^^^^^^^^^^^^^^^^^^^^^^^^^^^
  File "/home/ilya/code/webapps/pastebin-on-python/env/lib/python3.12/site-packages/django/template/base.py", line 966, in render_annotated
    return self.render(context)
           ^^^^^^^^^^^^^^^^^^^^
  File "/home/ilya/code/webapps/pastebin-on-python/env/lib/python3.12/site-packages/django/template/defaulttags.py", line 471, in render
    url = reverse(view_name, args=args, kwargs=kwargs, current_app=current_app)
          ^^^^^^^^^^^^^^^^^^^^^^^^^^^^^^^^^^^^^^^^^^^^^^^^^^^^^^^^^^^^^^^^^^^^^
  File "/home/ilya/code/webapps/pastebin-on-python/env/lib/python3.12/site-packages/django/urls/base.py", line 82, in reverse
    raise NoReverseMatch("%s is not a registered namespace" % key)
django.urls.exceptions.NoReverseMatch: 'savepost' is not a registered namespace
[2024-10-10 20:03:58.329810] Ошибка загрузки контента из S3! An error occurred (RequestTimeTooSkewed) when calling the GetObject operation: The difference between the request time and the current time is too large.
